<ns0:test-suite xmlns:ns0="urn:model.allure.qatools.yandex.ru" start="1546086058620" stop="1546086058672">
  <name>Test_001</name>
  <labels/>
  <test-cases>
    <test-case start="1546086058620" status="failed" stop="1546086058672">
      <name>TestAssert.test_a</name>
      <failure>
        <message>AssertionError: abc
assert 2 &gt; 3</message>
        <stack-trace>self = &lt;Test_001.TestAssert object at 0x0000000004235CF8&gt;

    def test_a(self):
&gt;       assert 2&gt;3,"abc"
E       AssertionError: abc
E       assert 2 &gt; 3

..\Test_001.py:10: AssertionError</stack-trace>
      </failure>
      <attachments/>
      <labels>
        <label name="severity" value="normal"/>
        <label name="thread" value="5896-MainThread"/>
        <label name="host" value="GTQYL412YJWMTFN"/>
        <label name="framework" value="pytest"/>
        <label name="language" value="cpython3"/>
      </labels>
      <steps/>
    </test-case>
  </test-cases>
</ns0:test-suite>
